Workbook

Sheet housing- Dataset
A1: price | B1: area | C1: bedrooms | D1: bathrooms | E1: stories | F1: mainroad | G1: guestroom | H1: basement | I1: hotwaterheating | J1: airconditioning | K1: parking | L1: prefarea | M1: furnishingstatus
A2: 13300000 | B2: 7420 | C2: 4 | D2: 2 | E2: 3 | F2: yes | G2: no | H2: no | I2: no | J2: yes | K2: 2 | L2: yes | M2: furnished
A3: 16800000 | B3: 8960 | C3: 4 | D3: 4 | E3: 4 | F3: yes | G3: no | H3: no | I3: no | J3: yes | K3: 3 | L3: no | M3: furnished
A4: 14900000 | B4: 9960 | C4: 3 | D4: 2 | E4: 2 | F4: yes | G4: no | H4: yes | I4: no | J4: no | K4: 2 | L4: yes | M4: semi-furnished
A5: 13650000 | B5: 7500 | C5: 4 | D5: 2 | E5: 2 | F5: yes | G5: no | H5: yes | I5: no | J5: yes | K5: 3 | L5: yes | M5: furnished
A6: 12200000 | B6: 7420 | C6: 4 | D6: 1 | E6: 2 | F6: yes | G6: yes | H6: yes | I6: no | J6: yes | K6: 2 | L6: no | M6: furnished
A7: 11200000 | B7: 6500 | C7: 3 | D7: 2 | E7: 2 | F7: yes | G7: no | H7: no | I7: no | J7: yes | K7: 2 | L7: yes | M7: semi-furnished
A8: 8100000 | B8: 4800 | C8: 3 | D8: 2 | E8: 1 | F8: yes | G8: no | H8: yes | I8: no | J8: no | K8: 1 | L8: no | M8: unfurnished
A9: 11950000 | B9: 5400 | C9: 4 | D9: 3 | E9: 2 | F9: yes | G9: yes | H9: no | I9: no | J9: yes | K9: 2 | L9: yes | M9: furnished
A10: 5200000 | B10: 3200 | C10: 2 | D10: 1 | E10: 1 | F10: no | G10: no | H10: no | I10: no | J10: no | K10: 0 | L10: no | M10: unfurnished
A11: 7600000 | B11: 4100 | C11: 3 | D11: 1 | E11: 2 | F11: yes | G11: no | H11: yes | I11: no | J11: no | K11: 1 | L11: no | M11: semi-furnished
A12: 10800000 | B12: 5600 | C12: 3 | D12: 2 | E12: 2 | F12: yes | G12: no | H12: no | I12: no | J12: yes | K12: 2 | L12: yes | M12: furnished
A13: 13100000 | B13: 6200 | C13: 4 | D13: 3 | E13: 3 | F13: yes | G13: yes | H13: yes | I13: no | J13: yes | K13: 2 | L13: yes | M13: furnished
... A201: 5550000 | B201: 5200 | C201: 4 | D201: 2 | E201: 2 | F201: yes | G201: no | H201: yes | I201: no | J201: yes | K201: 2 | L201: no | M201: semi-furnished

Sheet cleaning
A1: price | B1: area | C1: bedrooms | D1: bathrooms | E1: stories | F1: mainroad | G1: guestroom | H1: basement | I1: hotwaterheating | J1: airconditioning | K1: parking | L1: prefarea | M1: furnishingstatus | N1: semi-furnishingstatus
A2: 13300000 | B2: 7420 | C2: 4 | D2: 2 | E2: 3 | F2: 1 | G2: 0 | H2: 0 | I2: 0 | J2: 1 | K2: 2 | L2: 1 | M2: 1 | N2: 0
A3: 16800000 | B3: 8960 | C3: 4 | D3: 4 | E3: 4 | F3: 1 | G3: 0 | H3: 0 | I3: 0 | J3: 1 | K3: 3 | L3: 0 | M3: 1 | N3: 0
A4: 14900000 | B4: 9960 | C4: 3 | D4: 2 | E4: 2 | F4: 1 | G4: 0 | H4: 1 | I4: 0 | J4: 0 | K4: 2 | L4: 1 | M4: 0 | N4: 1
A5: 13650000 | B5: 7500 | C5: 4 | D5: 2 | E5: 2 | F5: 1 | G5: 0 | H5: 1 | I5: 0 | J5: 1 | K5: 3 | L5: 1 | M5: 1 | N5: 0
A6: 12200000 | B6: 7420 | C6: 4 | D6: 1 | E6: 2 | F6: 1 | G6: 1 | H6: 1 | I6: 0 | J6: 1 | K6: 2 | L6: 0 | M6: 1 | N6: 0
A7: 11200000 | B7: 6500 | C7: 3 | D7: 2 | E7: 2 | F7: 1 | G7: 0 | H7: 0 | I7: 0 | J7: 1 | K7: 2 | L7: 1 | M7: 0 | N7: 1
A8: 8100000 | B8: 4800 | C8: 3 | D8: 2 | E8: 1 | F8: 1 | G8: 0 | H8: 1 | I8: 0 | J8: 0 | K8: 1 | L8: 0 | M8: 0 | N8: 0
A9: 11950000 | B9: 5400 | C9: 4 | D9: 3 | E9: 2 | F9: 1 | G9: 1 | H9: 0 | I9: 0 | J9: 1 | K9: 2 | L9: 1 | M9: 1 | N9: 0
A10: 5200000 | B10: 3200 | C10: 2 | D10: 1 | E10: 1 | F10: 0 | G10: 0 | H10: 0 | I10: 0 | J10: 0 | K10: 0 | L10: 0 | M10: 0 | N10: 0
A11: 7600000 | B11: 4100 | C11: 3 | D11: 1 | E11: 2 | F11: 1 | G11: 0 | H11: 1 | I11: 0 | J11: 0 | K11: 1 | L11: 0 | M11: 0 | N11: 1
A12: 10800000 | B12: 5600 | C12: 3 | D12: 2 | E12: 2 | F12: 1 | G12: 0 | H12: 0 | I12: 0 | J12: 1 | K12: 2 | L12: 1 | M12: 1 | N12: 0
A13: 13100000 | B13: 6200 | C13: 4 | D13: 3 | E13: 3 | F13: 1 | G13: 1 | H13: 1 | I13: 0 | J13: 1 | K13: 2 | L13: 1 | M13: 1 | N13: 0
... A201: 5550000 | B201: 5200 | C201: 4 | D201: 2 | E201: 2 | F201: 1 | G201: 0 | H201: 1 | I201: 0 | J201: 1 | K201: 2 | L201: 0 | M201: 0 | N201: 1

Sheet outliar droping(1)
A1: price | B1: area | C1: bedrooms | D1: bathrooms | E1: stories | F1: mainroad | G1: guestroom | H1: basement | I1: hotwaterheating | J1: airconditioning | K1: parking | L1: prefarea | M1: furnishingstatus | N1: semi-furnishingstatus | P1: Outliar finding
A2: 13300000 | B2: 7420 | C2: 4 | D2: 2 | E2: 3 | F2: 1 | G2: 0 | H2: 0 | I2: 0 | J2: 1 | K2: 2 | L2: 1 | M2: 1 | N2: 0 | P2: =IF(AND(Table1_25[[#This Row],[price]]>R$12,Table1_25[[#This Row],[price]]<S$12),Table1_25[[#This Row],[price]],"") -> 13300000 | R2: Median | S2: Mean
A3: 16800000 | B3: 8960 | C3: 4 | D3: 4 | E3: 4 | F3: 1 | G3: 0 | H3: 0 | I3: 0 | J3: 1 | K3: 3 | L3: 0 | M3: 1 | N3: 0 | P3: =IF(AND(Table1_25[[#This Row],[price]]>R$12,Table1_25[[#This Row],[price]]<S$12),Table1_25[[#This Row],[price]],"") | R3: =MEDIAN(Table1_25[price]) -> 6075000 | S3: =AVERAGE(Table1_25[price]) -> 12267500
A4: 14900000 | B4: 9960 | C4: 3 | D4: 2 | E4: 2 | F4: 1 | G4: 0 | H4: 1 | I4: 0 | J4: 0 | K4: 2 | L4: 1 | M4: 0 | N4: 1 | P4: =IF(AND(Table1_25[[#This Row],[price]]>R$12,Table1_25[[#This Row],[price]]<S$12),Table1_25[[#This Row],[price]],"")
A5: 13650000 | B5: 7500 | C5: 4 | D5: 2 | E5: 2 | F5: 1 | G5: 0 | H5: 1 | I5: 0 | J5: 1 | K5: 3 | L5: 1 | M5: 1 | N5: 0 | P5: =IF(AND(Table1_25[[#This Row],[price]]>R$12,Table1_25[[#This Row],[price]]<S$12),Table1_25[[#This Row],[price]],"") -> 13650000 | R5: Q1 | S5: Q3
A6: 12200000 | B6: 7420 | C6: 4 | D6: 1 | E6: 2 | F6: 1 | G6: 1 | H6: 1 | I6: 0 | J6: 1 | K6: 2 | L6: 0 | M6: 1 | N6: 0 | P6: =IF(AND(Table1_25[[#This Row],[price]]>R$12,Table1_25[[#This Row],[price]]<S$12),Table1_25[[#This Row],[price]],"") -> 12200000 | R6: =_xlfn.QUARTILE.INC(Table1_25[price],1) -> 4750000 | S6: =_xlfn.QUARTILE.INC(Table1_25[price],3) -> 8350000
A7: 11200000 | B7: 6500 | C7: 3 | D7: 2 | E7: 2 | F7: 1 | G7: 0 | H7: 0 | I7: 0 | J7: 1 | K7: 2 | L7: 1 | M7: 0 | N7: 1 | P7: =IF(AND(Table1_25[[#This Row],[price]]>R$12,Table1_25[[#This Row],[price]]<S$12),Table1_25[[#This Row],[price]],"") -> 11200000
A8: 8100000 | B8: 4800 | C8: 3 | D8: 2 | E8: 1 | F8: 1 | G8: 0 | H8: 1 | I8: 0 | J8: 0 | K8: 1 | L8: 0 | M8: 0 | N8: 0 | P8: =IF(AND(Table1_25[[#This Row],[price]]>R$12,Table1_25[[#This Row],[price]]<S$12),Table1_25[[#This Row],[price]],"") -> 8100000 | R8: IQR
A9: 11950000 | B9: 5400 | C9: 4 | D9: 3 | E9: 2 | F9: 1 | G9: 1 | H9: 0 | I9: 0 | J9: 1 | K9: 2 | L9: 1 | M9: 1 | N9: 0 | P9: =IF(AND(Table1_25[[#This Row],[price]]>R$12,Table1_25[[#This Row],[price]]<S$12),Table1_25[[#This Row],[price]],"") -> 11950000 | R9: =S6-R6 -> 3600000
A10: 5200000 | B10: 3200 | C10: 2 | D10: 1 | E10: 1 | F10: 0 | G10: 0 | H10: 0 | I10: 0 | J10: 0 | K10: 0 | L10: 0 | M10: 0 | N10: 0 | P10: =IF(AND(Table1_25[[#This Row],[price]]>R$12,Table1_25[[#This Row],[price]]<S$12),Table1_25[[#This Row],[price]],"") -> 5200000
A11: 7600000 | B11: 4100 | C11: 3 | D11: 1 | E11: 2 | F11: 1 | G11: 0 | H11: 1 | I11: 0 | J11: 0 | K11: 1 | L11: 0 | M11: 0 | N11: 1 | P11: =IF(AND(Table1_25[[#This Row],[price]]>R$12,Table1_25[[#This Row],[price]]<S$12),Table1_25[[#This Row],[price]],"") -> 7600000 | R11: LOWER BOUND | S11: UPPER BOUND
A12: 10800000 | B12: 5600 | C12: 3 | D12: 2 | E12: 2 | F12: 1 | G12: 0 | H12: 0 | I12: 0 | J12: 1 | K12: 2 | L12: 1 | M12: 1 | N12: 0 | P12: =IF(AND(Table1_25[[#This Row],[price]]>R$12,Table1_25[[#This Row],[price]]<S$12),Table1_25[[#This Row],[price]],"") -> 10800000 | R12: =R6-1.5*R9 -> -650000 | S12: =S6+1.5*R9 -> 13750000
A13: 13100000 | B13: 6200 | C13: 4 | D13: 3 | E13: 3 | F13: 1 | G13: 1 | H13: 1 | I13: 0 | J13: 1 | K13: 2 | L13: 1 | M13: 1 | N13: 0 | P13: =IF(AND(Table1_25[[#This Row],[price]]>R$12,Table1_25[[#This Row],[price]]<S$12),Table1_25[[#This Row],[price]],"") -> 13100000
A14: 6100000 | B14: 3700 | C14: 2 | D14: 1 | E14: 1 | F14: 1 | G14: 0 | H14: 0 | I14: 0 | J14: 0 | K14: 1 | L14: 0 | M14: 0 | N14: 0 | P14: =IF(AND(Table1_25[[#This Row],[price]]>R$12,Table1_25[[#This Row],[price]]<S$12),Table1_25[[#This Row],[price]],"") -> 6100000
A15: 8900000 | B15: 4550 | C15: 3 | D15: 2 | E15: 2 | F15: 0 | G15: 0 | H15: 1 | I15: 0 | J15: 1 | K15: 1 | L15: 0 | M15: 0 | N15: 1 | P15: =IF(AND(Table1_25[[#This Row],[price]]>R$12,Table1_25[[#This Row],[price]]<S$12),Table1_25[[#This Row],[price]],"") -> 8900000 | R15: count outliars
A16: 13800000 | B16: 7000 | C16: 4 | D16: 3 | E16: 2 | F16: 1 | G16: 1 | H16: 0 | I16: 0 | J16: 1 | K16: 3 | L16: 1 | M16: 1 | N16: 0 | P16: =IF(AND(Table1_25[[#This Row],[price]]>R$12,Table1_25[[#This Row],[price]]<S$12),Table1_25[[#This Row],[price]],"") | R16: =COUNTBLANK(P2:P201) -> 34
A17: 4500000 | B17: 2850 | C17: 2 | D17: 1 | E17: 1 | F17: 0 | G17: 0 | H17: 0 | I17: 0 | J17: 0 | K17: 0 | L17: 0 | M17: 0 | N17: 0 | P17: =IF(AND(Table1_25[[#This Row],[price]]>R$12,Table1_25[[#This Row],[price]]<S$12),Table1_25[[#This Row],[price]],"") -> 4500000
A18: 10100000 | B18: 5100 | C18: 3 | D18: 2 | E18: 2 | F18: 1 | G18: 0 | H18: 0 | I18: 0 | J18: 1 | K18: 2 | L18: 0 | M18: 0 | N18: 1 | P18: =IF(AND(Table1_25[[#This Row],[price]]>R$12,Table1_25[[#This Row],[price]]<S$12),Table1_25[[#This Row],[price]],"") -> 10100000
A19: 14100000 | B19: 6800 | C19: 4 | D19: 2 | E19: 3 | F19: 1 | G19: 1 | H19: 1 | I19: 0 | J19: 1 | K19: 2 | L19: 1 | M19: 1 | N19: 0 | P19: =IF(AND(Table1_25[[#This Row],[price]]>R$12,Table1_25[[#This Row],[price]]<S$12),Table1_25[[#This Row],[price]],"")
A20: 6500000 | B20: 3950 | C20: 2 | D20: 1 | E20: 1 | F20: 1 | G20: 0 | H20: 0 | I20: 0 | J20: 0 | K20: 1 | L20: 0 | M20: 0 | N20: 0 | P20: =IF(AND(Table1_25[[#This Row],[price]]>R$12,Table1_25[[#This Row],[price]]<S$12),Table1_25[[#This Row],[price]],"") -> 6500000
A21: 11400000 | B21: 5900 | C21: 3 | D21: 2 | E21: 2 | F21: 1 | G21: 0 | H21: 1 | I21: 0 | J21: 1 | K21: 2 | L21: 1 | M21: 0 | N21: 1 | P21: =IF(AND(Table1_25[[#This Row],[price]]>R$12,Table1_25[[#This Row],[price]]<S$12),Table1_25[[#This Row],[price]],"") -> 11400000
A22: 5200000 | B22: 4600 | C22: 3 | D22: 2 | E22: 2 | F22: 1 | G22: 0 | H22: 0 | I22: 0 | J22: 1 | K22: 2 | L22: 0 | M22: 0 | N22: 1 | P22: =IF(AND(Table1_25[[#This Row],[price]]>R$12,Table1_25[[#This Row],[price]]<S$12),Table1_25[[#This Row],[price]],"") -> 5200000
A23: 6100000 | B23: 5800 | C23: 4 | D23: 3 | E23: 2 | F23: 1 | G23: 1 | H23: 0 | I23: 0 | J23: 1 | K23: 2 | L23: 1 | M23: 1 | N23: 0 | P23: =IF(AND(Table1_25[[#This Row],[price]]>R$12,Table1_25[[#This Row],[price]]<S$12),Table1_25[[#This Row],[price]],"") -> 6100000
A24: 3950000 | B24: 3500 | C24: 2 | D24: 1 | E24: 1 | F24: 0 | G24: 0 | H24: 0 | I24: 0 | J24: 0 | K24: 1 | L24: 0 | M24: 0 | N24: 0 | P24: =IF(AND(Table1_25[[#This Row],[price]]>R$12,Table1_25[[#This Row],[price]]<S$12),Table1_25[[#This Row],[price]],"") -> 3950000
A25: 7200000 | B25: 6400 | C25: 4 | D25: 3 | E25: 3 | F25: 1 | G25: 1 | H25: 1 | I25: 0 | J25: 1 | K25: 2 | L25: 1 | M25: 1 | N25: 0 | P25: =IF(AND(Table1_25[[#This Row],[price]]>R$12,Table1_25[[#This Row],[price]]<S$12),Table1_25[[#This Row],[price]],"") -> 7200000
A26: 4550000 | B26: 4100 | C26: 3 | D26: 2 | E26: 1 | F26: 1 | G26: 0 | H26: 0 | I26: 0 | J26: 0 | K26: 2 | L26: 0 | M26: 0 | N26: 1 | P26: =IF(AND(Table1_25[[#This Row],[price]]>R$12,Table1_25[[#This Row],[price]]<S$12),Table1_25[[#This Row],[price]],"") -> 4550000
A27: 6850000 | B27: 6000 | C27: 4 | D27: 2 | E27: 2 | F27: 1 | G27: 1 | H27: 0 | I27: 0 | J27: 1 | K27: 2 | L27: 1 | M27: 1 | N27: 0 | P27: =IF(AND(Table1_25[[#This Row],[price]]>R$12,Table1_25[[#This Row],[price]]<S$12),Table1_25[[#This Row],[price]],"") -> 6850000
A28: 5400000 | B28: 5000 | C28: 3 | D28: 2 | E28: 2 | F28: 1 | G28: 0 | H28: 1 | I28: 0 | J28: 1 | K28: 2 | L28: 0 | M28: 0 | N28: 1 | P28: =IF(AND(Table1_25[[#This Row],[price]]>R$12,Table1_25[[#This Row],[price]]<S$12),Table1_25[[#This Row],[price]],"") -> 5400000
... A201: 5550000 | B201: 5200 | C201: 4 | D201: 2 | E201: 2 | F201: 1 | G201: 0 | H201: 1 | I201: 0 | J201: 1 | K201: 2 | L201: 0 | M201: 0 | N201: 1 | P201: =IF(AND(Table1_25[[#This Row],[price]]>R$12,Table1_25[[#This Row],[price]]<S$12),Table1_25[[#This Row],[price]],"") -> 5550000

Sheet outliar droping(2)
A1: =Table1_25[[#Headers],[price]] -> price | B1: =Table1_25[[#Headers],[area]] -> area | C1: =Table1_25[[#Headers],[bedrooms]] -> bedrooms | D1: =Table1_25[[#Headers],[bathrooms]] -> bathrooms | E1: =Table1_25[[#Headers],[stories]] -> stories | F1: =Table1_25[[#Headers],[mainroad]] -> mainroad | G1: =Table1_25[[#Headers],[guestroom]] -> guestroom | H1: =Table1_25[[#Headers],[basement]] -> basement | I1: =Table1_25[[#Headers],[hotwaterheating]] -> hotwaterheating | J1: =Table1_25[[#Headers],[airconditioning]] -> airconditioning | K1: =Table1_25[[#Headers],[parking]] -> parking | L1: =Table1_25[[#Headers],[prefarea]] -> prefarea | M1: =Table1_25[[#Headers],[furnishingstatus]] -> furnishingstatus | N1: =Table1_25[[#Headers],[semi-furnishingstatus]] -> semi-furnishingstatus
A2: {=IF(Table1_25[[#This Row],[price]]='outliar droping(1)'!P2,Table1_25[#This Row],"")} -> 13300000 | B2: 7420 | C2: 4 | D2: 2 | E2: 3 | F2: 1 | G2: 0 | H2: 0 | I2: 0 | J2: 1 | K2: 2 | L2: 1 | M2: 1 | N2: 0
A3: {=IF(Table1_25[[#This Row],[price]]='outliar droping(1)'!P3,Table1_25[#This Row],"")}
A4: {=IF(Table1_25[[#This Row],[price]]='outliar droping(1)'!P4,Table1_25[#This Row],"")}
A5: {=IF(Table1_25[[#This Row],[price]]='outliar droping(1)'!P5,Table1_25[#This Row],"")} -> 13650000 | B5: 7500 | C5: 4 | D5: 2 | E5: 2 | F5: 1 | G5: 0 | H5: 1 | I5: 0 | J5: 1 | K5: 3 | L5: 1 | M5: 1 | N5: 0
A6: {=IF(Table1_25[[#This Row],[price]]='outliar droping(1)'!P6,Table1_25[#This Row],"")} -> 12200000 | B6: 7420 | C6: 4 | D6: 1 | E6: 2 | F6: 1 | G6: 1 | H6: 1 | I6: 0 | J6: 1 | K6: 2 | L6: 0 | M6: 1 | N6: 0
A7: {=IF(Table1_25[[#This Row],[price]]='outliar droping(1)'!P7,Table1_25[#This Row],"")} -> 11200000 | B7: 6500 | C7: 3 | D7: 2 | E7: 2 | F7: 1 | G7: 0 | H7: 0 | I7: 0 | J7: 1 | K7: 2 | L7: 1 | M7: 0 | N7: 1
A8: {=IF(Table1_25[[#This Row],[price]]='outliar droping(1)'!P8,Table1_25[#This Row],"")} -> 8100000 | B8: 4800 | C8: 3 | D8: 2 | E8: 1 | F8: 1 | G8: 0 | H8: 1 | I8: 0 | J8: 0 | K8: 1 | L8: 0 | M8: 0 | N8: 0
A9: {=IF(Table1_25[[#This Row],[price]]='outliar droping(1)'!P9,Table1_25[#This Row],"")} -> 11950000 | B9: 5400 | C9: 4 | D9: 3 | E9: 2 | F9: 1 | G9: 1 | H9: 0 | I9: 0 | J9: 1 | K9: 2 | L9: 1 | M9: 1 | N9: 0
A10: {=IF(Table1_25[[#This Row],[price]]='outliar droping(1)'!P10,Table1_25[#This Row],"")} -> 5200000 | B10: 3200 | C10: 2 | D10: 1 | E10: 1 | F10: 0 | G10: 0 | H10: 0 | I10: 0 | J10: 0 | K10: 0 | L10: 0 | M10: 0 | N10: 0
A11: {=IF(Table1_25[[#This Row],[price]]='outliar droping(1)'!P11,Table1_25[#This Row],"")} -> 7600000 | B11: 4100 | C11: 3 | D11: 1 | E11: 2 | F11: 1 | G11: 0 | H11: 1 | I11: 0 | J11: 0 | K11: 1 | L11: 0 | M11: 0 | N11: 1
A12: {=IF(Table1_25[[#This Row],[price]]='outliar droping(1)'!P12,Table1_25[#This Row],"")} -> 10800000 | B12: 5600 | C12: 3 | D12: 2 | E12: 2 | F12: 1 | G12: 0 | H12: 0 | I12: 0 | J12: 1 | K12: 2 | L12: 1 | M12: 1 | N12: 0
A13: {=IF(Table1_25[[#This Row],[price]]='outliar droping(1)'!P13,Table1_25[#This Row],"")} -> 13100000 | B13: 6200 | C13: 4 | D13: 3 | E13: 3 | F13: 1 | G13: 1 | H13: 1 | I13: 0 | J13: 1 | K13: 2 | L13: 1 | M13: 1 | N13: 0
A14: {=IF(Table1_25[[#This Row],[price]]='outliar droping(1)'!P14,Table1_25[#This Row],"")} -> 6100000 | B14: 3700 | C14: 2 | D14: 1 | E14: 1 | F14: 1 | G14: 0 | H14: 0 | I14: 0 | J14: 0 | K14: 1 | L14: 0 | M14: 0 | N14: 0
A15: {=IF(Table1_25[[#This Row],[price]]='outliar droping(1)'!P15,Table1_25[#This Row],"")} -> 8900000 | B15: 4550 | C15: 3 | D15: 2 | E15: 2 | F15: 0 | G15: 0 | H15: 1 | I15: 0 | J15: 1 | K15: 1 | L15: 0 | M15: 0 | N15: 1
A16: {=IF(Table1_25[[#This Row],[price]]='outliar droping(1)'!P16,Table1_25[#This Row],"")}
A17: {=IF(Table1_25[[#This Row],[price]]='outliar droping(1)'!P17,Table1_25[#This Row],"")} -> 4500000 | B17: 2850 | C17: 2 | D17: 1 | E17: 1 | F17: 0 | G17: 0 | H17: 0 | I17: 0 | J17: 0 | K17: 0 | L17: 0 | M17: 0 | N17: 0
A18: {=IF(Table1_25[[#This Row],[price]]='outliar droping(1)'!P18,Table1_25[#This Row],"")} -> 10100000 | B18: 5100 | C18: 3 | D18: 2 | E18: 2 | F18: 1 | G18: 0 | H18: 0 | I18: 0 | J18: 1 | K18: 2 | L18: 0 | M18: 0 | N18: 1
A19: {=IF(Table1_25[[#This Row],[price]]='outliar droping(1)'!P19,Table1_25[#This Row],"")}
A20: {=IF(Table1_25[[#This Row],[price]]='outliar droping(1)'!P20,Table1_25[#This Row],"")} -> 6500000 | B20: 3950 | C20: 2 | D20: 1 | E20: 1 | F20: 1 | G20: 0 | H20: 0 | I20: 0 | J20: 0 | K20: 1 | L20: 0 | M20: 0 | N20: 0
A21: {=IF(Table1_25[[#This Row],[price]]='outliar droping(1)'!P21,Table1_25[#This Row],"")} -> 11400000 | B21: 5900 | C21: 3 | D21: 2 | E21: 2 | F21: 1 | G21: 0 | H21: 1 | I21: 0 | J21: 1 | K21: 2 | L21: 1 | M21: 0 | N21: 1
A22: {=IF(Table1_25[[#This Row],[price]]='outliar droping(1)'!P22,Table1_25[#This Row],"")} -> 5200000 | B22: 4600 | C22: 3 | D22: 2 | E22: 2 | F22: 1 | G22: 0 | H22: 0 | I22: 0 | J22: 1 | K22: 2 | L22: 0 | M22: 0 | N22: 1
A23: {=IF(Table1_25[[#This Row],[price]]='outliar droping(1)'!P23,Table1_25[#This Row],"")} -> 6100000 | B23: 5800 | C23: 4 | D23: 3 | E23: 2 | F23: 1 | G23: 1 | H23: 0 | I23: 0 | J23: 1 | K23: 2 | L23: 1 | M23: 1 | N23: 0
A24: {=IF(Table1_25[[#This Row],[price]]='outliar droping(1)'!P24,Table1_25[#This Row],"")} -> 3950000 | B24: 3500 | C24: 2 | D24: 1 | E24: 1 | F24: 0 | G24: 0 | H24: 0 | I24: 0 | J24: 0 | K24: 1 | L24: 0 | M24: 0 | N24: 0
A25: {=IF(Table1_25[[#This Row],[price]]='outliar droping(1)'!P25,Table1_25[#This Row],"")} -> 7200000 | B25: 6400 | C25: 4 | D25: 3 | E25: 3 | F25: 1 | G25: 1 | H25: 1 | I25: 0 | J25: 1 | K25: 2 | L25: 1 | M25: 1 | N25: 0
A26: {=IF(Table1_25[[#This Row],[price]]='outliar droping(1)'!P26,Table1_25[#This Row],"")} -> 4550000 | B26: 4100 | C26: 3 | D26: 2 | E26: 1 | F26: 1 | G26: 0 | H26: 0 | I26: 0 | J26: 0 | K26: 2 | L26: 0 | M26: 0 | N26: 1
A27: {=IF(Table1_25[[#This Row],[price]]='outliar droping(1)'!P27,Table1_25[#This Row],"")} -> 6850000 | B27: 6000 | C27: 4 | D27: 2 | E27: 2 | F27: 1 | G27: 1 | H27: 0 | I27: 0 | J27: 1 | K27: 2 | L27: 1 | M27: 1 | N27: 0
A28: {=IF(Table1_25[[#This Row],[price]]='outliar droping(1)'!P28,Table1_25[#This Row],"")} -> 5400000 | B28: 5000 | C28: 3 | D28: 2 | E28: 2 | F28: 1 | G28: 0 | H28: 1 | I28: 0 | J28: 1 | K28: 2 | L28: 0 | M28: 0 | N28: 1
A29: {=IF(Table1_25[[#This Row],[price]]='outliar droping(1)'!P29,Table1_25[#This Row],"")} -> 3350000 | B29: 3000 | C29: 2 | D29: 1 | E29: 1 | F29: 0 | G29: 0 | H29: 0 | I29: 0 | J29: 0 | K29: 1 | L29: 0 | M29: 0 | N29: 0
A30: {=IF(Table1_25[[#This Row],[price]]='outliar droping(1)'!P30,Table1_25[#This Row],"")} -> 8100000 | B30: 7200 | C30: 5 | D30: 3 | E30: 3 | F30: 1 | G30: 1 | H30: 1 | I30: 0 | J30: 1 | K30: 3 | L30: 1 | M30: 1 | N30: 0
A31: {=IF(Table1_25[[#This Row],[price]]='outliar droping(1)'!P31,Table1_25[#This Row],"")} -> 4900000 | B31: 4300 | C31: 3 | D31: 2 | E31: 2 | F31: 1 | G31: 0 | H31: 0 | I31: 0 | J31: 1 | K31: 2 | L31: 0 | M31: 0 | N31: 1
... A41: {=IF(Table1_25[[#This Row],[price]]='outliar droping(1)'!P41,Table1_25[#This Row],"")} -> 8350000 | B41: 7400 | C41: 5 | D41: 3 | E41: 3 | F41: 1 | G41: 1 | H41: 1 | I41: 0 | J41: 1 | K41: 3 | L41: 1 | M41: 1 | N41: 0
A42: {=IF(Table1_25[[#This Row],[price]]='outliar droping(1)'!P42,Table1_25[#This Row],"")}
A43: {=IF(Table1_25[[#This Row],[price]]='outliar droping(1)'!P43,Table1_25[#This Row],"")}
A44: {=IF(Table1_25[[#This Row],[price]]='outliar droping(1)'!P44,Table1_25[#This Row],"")}
A45: {=IF(Table1_25[[#This Row],[price]]='outliar droping(1)'!P45,Table1_25[#This Row],"")}
A46: {=IF(Table1_25[[#This Row],[price]]='outliar droping(1)'!P46,Table1_25[#This Row],"")}
A47: {=IF(Table1_25[[#This Row],[price]]='outliar droping(1)'!P47,Table1_25[#This Row],"")} -> 4400000 | B47: 4050 | C47: 3 | D47: 2 | E47: 1 | F47: 0 | G47: 0 | H47: 0 | I47: 0 | J47: 0 | K47: 2 | L47: 0 | M47: 0 | N47: 1
A48: {=IF(Table1_25[[#This Row],[price]]='outliar droping(1)'!P48,Table1_25[#This Row],"")} -> 5850000 | B48: 5600 | C48: 4 | D48: 2 | E48: 2 | F48: 1 | G48: 1 | H48: 0 | I48: 0 | J48: 1 | K48: 2 | L48: 1 | M48: 1 | N48: 0
A49: {=IF(Table1_25[[#This Row],[price]]='outliar droping(1)'!P49,Table1_25[#This Row],"")} -> 5050000 | B49: 4700 | C49: 3 | D49: 2 | E49: 2 | F49: 1 | G49: 0 | H49: 1 | I49: 0 | J49: 1 | K49: 2 | L49: 0 | M49: 0 | N49: 1
...

Sheet outliar droping(3)
A1: price | B1: area | C1: bedrooms | D1: bathrooms | E1: stories | F1: mainroad | G1: guestroom | H1: basement | I1: hotwaterheating | J1: airconditioning | K1: parking | L1: prefarea | M1: furnishingstatus | N1: semi-furnishingstatus
A2: 13300000 | B2: 7420 | C2: 4 | D2: 2 | E2: 3 | F2: 1 | G2: 0 | H2: 0 | I2: 0 | J2: 1 | K2: 2 | L2: 1 | M2: 1 | N2: 0
A5: 13650000 | B5: 7500 | C5: 4 | D5: 2 | E5: 2 | F5: 1 | G5: 0 | H5: 1 | I5: 0 | J5: 1 | K5: 3 | L5: 1 | M5: 1 | N5: 0
A6: 12200000 | B6: 7420 | C6: 4 | D6: 1 | E6: 2 | F6: 1 | G6: 1 | H6: 1 | I6: 0 | J6: 1 | K6: 2 | L6: 0 | M6: 1 | N6: 0
A7: 11200000 | B7: 6500 | C7: 3 | D7: 2 | E7: 2 | F7: 1 | G7: 0 | H7: 0 | I7: 0 | J7: 1 | K7: 2 | L7: 1 | M7: 0 | N7: 1
A8: 8100000 | B8: 4800 | C8: 3 | D8: 2 | E8: 1 | F8: 1 | G8: 0 | H8: 1 | I8: 0 | J8: 0 | K8: 1 | L8: 0 | M8: 0 | N8: 0
A9: 11950000 | B9: 5400 | C9: 4 | D9: 3 | E9: 2 | F9: 1 | G9: 1 | H9: 0 | I9: 0 | J9: 1 | K9: 2 | L9: 1 | M9: 1 | N9: 0
A10: 5200000 | B10: 3200 | C10: 2 | D10: 1 | E10: 1 | F10: 0 | G10: 0 | H10: 0 | I10: 0 | J10: 0 | K10: 0 | L10: 0 | M10: 0 | N10: 0
A11: 7600000 | B11: 4100 | C11: 3 | D11: 1 | E11: 2 | F11: 1 | G11: 0 | H11: 1 | I11: 0 | J11: 0 | K11: 1 | L11: 0 | M11: 0 | N11: 1
A12: 10800000 | B12: 5600 | C12: 3 | D12: 2 | E12: 2 | F12: 1 | G12: 0 | H12: 0 | I12: 0 | J12: 1 | K12: 2 | L12: 1 | M12: 1 | N12: 0
A13: 13100000 | B13: 6200 | C13: 4 | D13: 3 | E13: 3 | F13: 1 | G13: 1 | H13: 1 | I13: 0 | J13: 1 | K13: 2 | L13: 1 | M13: 1 | N13: 0
A14: 6100000 | B14: 3700 | C14: 2 | D14: 1 | E14: 1 | F14: 1 | G14: 0 | H14: 0 | I14: 0 | J14: 0 | K14: 1 | L14: 0 | M14: 0 | N14: 0
A15: 8900000 | B15: 4550 | C15: 3 | D15: 2 | E15: 2 | F15: 0 | G15: 0 | H15: 1 | I15: 0 | J15: 1 | K15: 1 | L15: 0 | M15: 0 | N15: 1
... A201: 5550000 | B201: 5200 | C201: 4 | D201: 2 | E201: 2 | F201: 1 | G201: 0 | H201: 1 | I201: 0 | J201: 1 | K201: 2 | L201: 0 | M201: 0 | N201: 1

Sheet test-train
A1: price | B1: area | C1: bedrooms | D1: bathrooms | E1: stories | F1: mainroad | G1: guestroom | H1: basement | I1: hotwaterheating | J1: airconditioning | K1: parking | L1: prefarea | M1: furnishingstatus | N1: semi-furnishingstatus | O1: Random | P1: Random (values) | Q1: Dataset
A2: 4450000 | B2: 4100 | C2: 3 | D2: 2 | E2: 1 | F2: 0 | G2: 0 | H2: 0 | I2: 0 | J2: 0 | K2: 2 | L2: 0 | M2: 0 | N2: 0 | O2: =RAND() -> 0.66789436 | P2: 0.069638787 | Q2: =IF(ROWS($A$2:A2)<=ROUND(COUNTA($A:$A)*80%,0),"Training","Testing") -> Training
A3: 3650000 | B3: 3200 | C3: 2 | D3: 1 | E3: 1 | F3: 0 | G3: 0 | H3: 0 | I3: 0 | J3: 0 | K3: 1 | L3: 0 | M3: 0 | N3: 0 | O3: =RAND() -> 0.84702503 | P3: 0.88118002 | Q3: =IF(ROWS($A$2:A3)<=ROUND(COUNTA($A:$A)*80%,0),"Training","Testing") -> Training
A4: 7750000 | B4: 7100 | C4: 5 | D4: 3 | E4: 3 | F4: 1 | G4: 1 | H4: 1 | I4: 0 | J4: 1 | K4: 3 | L4: 1 | M4: 1 | N4: 0 | O4: =RAND() -> 0.25122813 | P4: 0.42849079 | Q4: =IF(ROWS($A$2:A4)<=ROUND(COUNTA($A:$A)*80%,0),"Training","Testing") -> Training
A5: 5250000 | B5: 4850 | C5: 3 | D5: 2 | E5: 2 | F5: 1 | G5: 0 | H5: 0 | I5: 0 | J5: 1 | K5: 2 | L5: 0 | M5: 0 | N5: 1 | O5: =RAND() -> 0.068909023 | P5: 0.89218028 | Q5: =IF(ROWS($A$2:A5)<=ROUND(COUNTA($A:$A)*80%,0),"Training","Testing") -> Training
A6: 6450000 | B6: 5950 | C6: 4 | D6: 3 | E6: 2 | F6: 1 | G6: 1 | H6: 0 | I6: 0 | J6: 1 | K6: 2 | L6: 1 | M6: 1 | N6: 0 | O6: =RAND() -> 0.81619426 | P6: 0.49901139 | Q6: =IF(ROWS($A$2:A6)<=ROUND(COUNTA($A:$A)*80%,0),"Training","Testing") -> Training
A7: 4450000 | B7: 4100 | C7: 3 | D7: 2 | E7: 1 | F7: 0 | G7: 0 | H7: 0 | I7: 0 | J7: 0 | K7: 2 | L7: 0 | M7: 0 | N7: 0 | O7: =RAND() -> 0.011743299 | P7: 0.49871435 | Q7: =IF(ROWS($A$2:A7)<=ROUND(COUNTA($A:$A)*80%,0),"Training","Testing") -> Training
A8: 8350000 | B8: 7400 | C8: 5 | D8: 3 | E8: 3 | F8: 1 | G8: 1 | H8: 1 | I8: 0 | J8: 1 | K8: 3 | L8: 1 | M8: 1 | N8: 0 | O8: =RAND() -> 0.85651328 | P8: 0.69906201 | Q8: =IF(ROWS($A$2:A8)<=ROUND(COUNTA($A:$A)*80%,0),"Training","Testing") -> Training
A9: 3450000 | B9: 2950 | C9: 2 | D9: 1 | E9: 1 | F9: 0 | G9: 0 | H9: 0 | I9: 0 | J9: 0 | K9: 1 | L9: 0 | M9: 0 | N9: 0 | O9: =RAND() -> 0.45207553 | P9: 0.76531237 | Q9: =IF(ROWS($A$2:A9)<=ROUND(COUNTA($A:$A)*80%,0),"Training","Testing") -> Training
A10: 5550000 | B10: 5150 | C10: 4 | D10: 2 | E10: 2 | F10: 1 | G10: 0 | H10: 1 | I10: 0 | J10: 1 | K10: 2 | L10: 0 | M10: 0 | N10: 1 | O10: =RAND() -> 0.41589365 | P10: 0.010501618 | Q10: =IF(ROWS($A$2:A10)<=ROUND(COUNTA($A:$A)*80%,0),"Training","Testing") -> Training
A11: 7250000 | B11: 6600 | C11: 5 | D11: 3 | E11: 3 | F11: 1 | G11: 1 | H11: 1 | I11: 0 | J11: 1 | K11: 3 | L11: 1 | M11: 1 | N11: 0 | O11: =RAND() -> 0.94386176 | P11: 0.42999649 | Q11: =IF(ROWS($A$2:A11)<=ROUND(COUNTA($A:$A)*80%,0),"Training","Testing") -> Training
A12: 6750000 | B12: 6200 | C12: 4 | D12: 3 | E12: 2 | F12: 1 | G12: 1 | H12: 0 | I12: 0 | J12: 1 | K12: 2 | L12: 1 | M12: 1 | N12: 0 | O12: =RAND() -> 0.77626042 | P12: 0.86838924 | Q12: =IF(ROWS($A$2:A12)<=ROUND(COUNTA($A:$A)*80%,0),"Training","Testing") -> Training
A13: 8900000 | B13: 4550 | C13: 3 | D13: 2 | E13: 2 | F13: 0 | G13: 0 | H13: 1 | I13: 0 | J13: 1 | K13: 1 | L13: 0 | M13: 0 | N13: 1 | O13: =RAND() -> 0.18972953 | P13: 0.30677149 | Q13: =IF(ROWS($A$2:A13)<=ROUND(COUNTA($A:$A)*80%,0),"Training","Testing") -> Training
... A167: 4100000 | B167: 3550 | C167: 2 | D167: 1 | E167: 1 | F167: 0 | G167: 0 | H167: 0 | I167: 0 | J167: 0 | K167: 1 | L167: 0 | M167: 0 | N167: 0 | O167: =RAND() -> 0.87667014 | P167: 0.58282977 | Q167: =IF(ROWS($A$2:A167)<=ROUND(COUNTA($A:$A)*80%,0),"Training","Testing") -> Testing

Sheet train
A1: price | B1: area | C1: bedrooms | D1: bathrooms | E1: stories | F1: mainroad | G1: guestroom | H1: basement | I1: airconditioning | J1: parking | K1: prefarea | L1: furnishingstatus | M1: semi-furnishingstatus | N1: Random | O1: Random (values) | P1: Dataset | S1: SUMMARY OUTPUT
A2: 4450000 | B2: 4100 | C2: 3 | D2: 2 | E2: 1 | F2: 0 | G2: 0 | H2: 0 | I2: 0 | J2: 2 | K2: 0 | L2: 0 | M2: 0 | N2: =RAND() -> 0.042796063 | O2: 0.069638787 | P2: =IF(ROWS($A$2:A2)<=ROUND(COUNTA($A:$A)*80%,0),"Training","Testing") -> Training
A3: 3650000 | B3: 3200 | C3: 2 | D3: 1 | E3: 1 | F3: 0 | G3: 0 | H3: 0 | I3: 0 | J3: 1 | K3: 0 | L3: 0 | M3: 0 | N3: =RAND() -> 0.90281422 | O3: 0.88118002 | P3: =IF(ROWS($A$2:A3)<=ROUND(COUNTA($A:$A)*80%,0),"Training","Testing") -> Training | S3: Regression Statistics
A4: 7750000 | B4: 7100 | C4: 5 | D4: 3 | E4: 3 | F4: 1 | G4: 1 | H4: 1 | I4: 1 | J4: 3 | K4: 1 | L4: 1 | M4: 0 | N4: =RAND() -> 0.22620762 | O4: 0.42849079 | P4: =IF(ROWS($A$2:A4)<=ROUND(COUNTA($A:$A)*80%,0),"Training","Testing") -> Training | S4: Multiple R | T4: 0.87273524
A5: 5250000 | B5: 4850 | C5: 3 | D5: 2 | E5: 2 | F5: 1 | G5: 0 | H5: 0 | I5: 1 | J5: 2 | K5: 0 | L5: 0 | M5: 1 | N5: =RAND() -> 0.90508274 | O5: 0.89218028 | P5: =IF(ROWS($A$2:A5)<=ROUND(COUNTA($A:$A)*80%,0),"Training","Testing") -> Training | S5: R Square | T5: 0.7616668
A6: 6450000 | B6: 5950 | C6: 4 | D6: 3 | E6: 2 | F6: 1 | G6: 1 | H6: 0 | I6: 1 | J6: 2 | K6: 1 | L6: 1 | M6: 0 | N6: =RAND() -> 0.72070607 | O6: 0.49901139 | P6: =IF(ROWS($A$2:A6)<=ROUND(COUNTA($A:$A)*80%,0),"Training","Testing") -> Training | S6: Adjusted R Square | T6: 0.73803045
A7: 4450000 | B7: 4100 | C7: 3 | D7: 2 | E7: 1 | F7: 0 | G7: 0 | H7: 0 | I7: 0 | J7: 2 | K7: 0 | L7: 0 | M7: 0 | N7: =RAND() -> 0.2253149 | O7: 0.49871435 | P7: =IF(ROWS($A$2:A7)<=ROUND(COUNTA($A:$A)*80%,0),"Training","Testing") -> Training | S7: Standard Error | T7: 1026767.4
A8: 8350000 | B8: 7400 | C8: 5 | D8: 3 | E8: 3 | F8: 1 | G8: 1 | H8: 1 | I8: 1 | J8: 3 | K8: 1 | L8: 1 | M8: 0 | N8: =RAND() -> 0.94116717 | O8: 0.69906201 | P8: =IF(ROWS($A$2:A8)<=ROUND(COUNTA($A:$A)*80%,0),"Training","Testing") -> Training | S8: Observations | T8: 134
A9: 3450000 | B9: 2950 | C9: 2 | D9: 1 | E9: 1 | F9: 0 | G9: 0 | H9: 0 | I9: 0 | J9: 1 | K9: 0 | L9: 0 | M9: 0 | N9: =RAND() -> 0.40760211 | O9: 0.76531237 | P9: =IF(ROWS($A$2:A9)<=ROUND(COUNTA($A:$A)*80%,0),"Training","Testing") -> Training
A10: 5550000 | B10: 5150 | C10: 4 | D10: 2 | E10: 2 | F10: 1 | G10: 0 | H10: 1 | I10: 1 | J10: 2 | K10: 0 | L10: 0 | M10: 1 | N10: =RAND() -> 0.25170423 | O10: 0.010501618 | P10: =IF(ROWS($A$2:A10)<=ROUND(COUNTA($A:$A)*80%,0),"Training","Testing") -> Training | S10: ANOVA
A11: 7250000 | B11: 6600 | C11: 5 | D11: 3 | E11: 3 | F11: 1 | G11: 1 | H11: 1 | I11: 1 | J11: 3 | K11: 1 | L11: 1 | M11: 0 | N11: =RAND() -> 0.051849676 | O11: 0.42999649 | P11: =IF(ROWS($A$2:A11)<=ROUND(COUNTA($A:$A)*80%,0),"Training","Testing") -> Training | T11: df | U11: SS | V11: MS | W11: F | X11: Significance F
A12: 6750000 | B12: 6200 | C12: 4 | D12: 3 | E12: 2 | F12: 1 | G12: 1 | H12: 0 | I12: 1 | J12: 2 | K12: 1 | L12: 1 | M12: 0 | N12: =RAND() -> 0.28146057 | O12: 0.86838924 | P12: =IF(ROWS($A$2:A12)<=ROUND(COUNTA($A:$A)*80%,0),"Training","Testing") -> Training | S12: Regression | T12: 12 | U12: 4.0767119e+14 | V12: 3.3972599e+13 | W12: 32.224383 | X12: 4.7181015e-32
A13: 8900000 | B13: 4550 | C13: 3 | D13: 2 | E13: 2 | F13: 0 | G13: 0 | H13: 1 | I13: 1 | J13: 1 | K13: 0 | L13: 0 | M13: 1 | N13: =RAND() -> 0.1497097 | O13: 0.30677149 | P13: =IF(ROWS($A$2:A13)<=ROUND(COUNTA($A:$A)*80%,0),"Training","Testing") -> Training | S13: Residual | T13: 121 | U13: 1.2756441e+14 | V13: 1.0542513e+12
A14: 11400000 | B14: 5900 | C14: 3 | D14: 2 | E14: 2 | F14: 1 | G14: 0 | H14: 1 | I14: 1 | J14: 2 | K14: 1 | L14: 0 | M14: 1 | N14: =RAND() -> 0.25077256 | O14: 0.58381997 | P14: =IF(ROWS($A$2:A14)<=ROUND(COUNTA($A:$A)*80%,0),"Training","Testing") -> Training | S14: Total | T14: 133 | U14: 5.352356e+14
A15: 8450000 | B15: 7800 | C15: 5 | D15: 4 | E15: 3 | F15: 1 | G15: 1 | H15: 1 | I15: 1 | J15: 3 | K15: 1 | L15: 1 | M15: 0 | N15: =RAND() -> 0.096352602 | O15: 0.43155483 | P15: =IF(ROWS($A$2:A15)<=ROUND(COUNTA($A:$A)*80%,0),"Training","Testing") -> Training
A16: 4750000 | B16: 4400 | C16: 3 | D16: 2 | E16: 2 | F16: 1 | G16: 0 | H16: 0 | I16: 0 | J16: 2 | K16: 0 | L16: 0 | M16: 1 | N16: =RAND() -> 0.18935315 | O16: 0.34875593 | P16: =IF(ROWS($A$2:A16)<=ROUND(COUNTA($A:$A)*80%,0),"Training","Testing") -> Training | T16: Coefficients | U16: Standard Error | V16: t Stat | W16: P-value | X16: Lower 95% | Y16: Upper 95% | Z16: Lower 95,0% | AA16: Upper 95,0%
A17: 3600000 | B17: 3200 | C17: 2 | D17: 1 | E17: 1 | F17: 0 | G17: 0 | H17: 0 | I17: 0 | J17: 1 | K17: 0 | L17: 0 | M17: 0 | N17: =RAND() -> 0.3894622 | O17: 0.92049058 | P17: =IF(ROWS($A$2:A17)<=ROUND(COUNTA($A:$A)*80%,0),"Training","Testing") -> Training | S17: Intercept | T17: 29479.697 | U17: 740734.3 | V17: 0.039797936 | W17: 0.96831981 | X17: -1436999.2 | Y17: 1495958.6 | Z17: -1436999.2 | AA17: 1495958.6
A18: 4450000 | B18: 4100 | C18: 3 | D18: 2 | E18: 1 | F18: 0 | G18: 0 | H18: 0 | I18: 0 | J18: 2 | K18: 0 | L18: 0 | M18: 0 | N18: =RAND() -> 0.040490479 | O18: 0.68046833 | P18: =IF(ROWS($A$2:A18)<=ROUND(COUNTA($A:$A)*80%,0),"Training","Testing") -> Training | S18: area | T18: 2184.2917 | U18: 270.11891 | V18: 8.0864079 | W18: 5.3548281e-13 | X18: 1649.5201 | Y18: 2719.0633 | Z18: 1649.5201 | AA18: 2719.0633
A19: 5150000 | B19: 4700 | C19: 3 | D19: 2 | E19: 2 | F19: 1 | G19: 0 | H19: 0 | I19: 1 | J19: 2 | K19: 0 | L19: 0 | M19: 1 | N19: =RAND() -> 0.94295475 | O19: 0.78858349 | P19: =IF(ROWS($A$2:A19)<=ROUND(COUNTA($A:$A)*80%,0),"Training","Testing") -> Training | S19: bedrooms | T19: -803178.88 | U19: 345761.6 | V19: -2.3229268 | W19: 0.021853097 | X19: -1487705.2 | Y19: -118652.6 | Z19: -1487705.2 | AA19: -118652.6
A20: 4950000 | B20: 4550 | C20: 3 | D20: 2 | E20: 2 | F20: 1 | G20: 0 | H20: 0 | I20: 1 | J20: 2 | K20: 0 | L20: 0 | M20: 1 | N20: =RAND() -> 0.98068352 | O20: 0.05022788 | P20: =IF(ROWS($A$2:A20)<=ROUND(COUNTA($A:$A)*80%,0),"Training","Testing") -> Training | S20: bathrooms | T20: -446678.1 | U20: 282769.53 | V20: -1.5796543 | W20: 0.11679672 | X20: -1006495 | Y20: 113138.76 | Z20: -1006495 | AA20: 113138.76
A21: 6900000 | B21: 6300 | C21: 4 | D21: 3 | E21: 3 | F21: 1 | G21: 1 | H21: 1 | I21: 1 | J21: 3 | K21: 1 | L21: 1 | M21: 0 | N21: =RAND() -> 0.23890054 | O21: 0.11053297 | P21: =IF(ROWS($A$2:A21)<=ROUND(COUNTA($A:$A)*80%,0),"Training","Testing") -> Training | S21: stories | T21: 532097.05 | U21: 402563.43 | V21: 1.3217719 | W21: 0.18873764 | X21: -264883.45 | Y21: 1329077.5 | Z21: -264883.45 | AA21: 1329077.5
A22: 4800000 | B22: 4450 | C22: 3 | D22: 2 | E22: 2 | F22: 1 | G22: 0 | H22: 0 | I22: 1 | J22: 2 | K22: 0 | L22: 0 | M22: 1 | N22: =RAND() -> 0.34436184 | O22: 0.50441912 | P22: =IF(ROWS($A$2:A22)<=ROUND(COUNTA($A:$A)*80%,0),"Training","Testing") -> Training | S22: mainroad | T22: -43488.551 | U22: 466239.99 | V22: -0.093275033 | W22: 0.92583933 | X22: -966533.59 | Y22: 879556.49 | Z22: -966533.59 | AA22: 879556.49
A23: 5200000 | B23: 4600 | C23: 3 | D23: 2 | E23: 2 | F23: 1 | G23: 0 | H23: 0 | I23: 1 | J23: 2 | K23: 0 | L23: 0 | M23: 1 | N23: =RAND() -> 0.64398176 | O23: 0.99167088 | P23: =IF(ROWS($A$2:A23)<=ROUND(COUNTA($A:$A)*80%,0),"Training","Testing") -> Training | S23: guestroom | T23: -2892120.8 | U23: 822110.5 | V23: -3.5179222 | W23: 0.00061342696 | X23: -4519705.3 | Y23: -1264536.2 | Z23: -4519705.3 | AA23: -1264536.2
A24: 4750000 | B24: 4400 | C24: 3 | D24: 2 | E24: 2 | F24: 1 | G24: 0 | H24: 0 | I24: 0 | J24: 2 | K24: 0 | L24: 0 | M24: 1 | N24: =RAND() -> 0.28706548 | O24: 0.67714346 | P24: =IF(ROWS($A$2:A24)<=ROUND(COUNTA($A:$A)*80%,0),"Training","Testing") -> Training | S24: basement | T24: 271881.69 | U24: 286978.83 | V24: 0.94739285 | W24: 0.34532685 | X24: -296268.59 | Y24: 840031.97 | Z24: -296268.59 | AA24: 840031.97
A25: 7450000 | B25: 6800 | C25: 5 | D25: 3 | E25: 3 | F25: 1 | G25: 1 | H25: 1 | I25: 1 | J25: 3 | K25: 1 | L25: 1 | M25: 0 | N25: =RAND() -> 0.76591368 | O25: 0.38249651 | P25: =IF(ROWS($A$2:A25)<=ROUND(COUNTA($A:$A)*80%,0),"Training","Testing") -> Training | S25: airconditioning | T25: -661981.15 | U25: 457767.14 | V25: -1.4461089 | W25: 0.15073197 | X25: -1568252 | Y25: 244289.65 | Z25: -1568252 | AA25: 244289.65
A26: 6650000 | B26: 6150 | C26: 4 | D26: 3 | E26: 2 | F26: 1 | G26: 1 | H26: 0 | I26: 1 | J26: 2 | K26: 1 | L26: 1 | M26: 0 | N26: =RAND() -> 0.37218096 | O26: 0.61882182 | P26: =IF(ROWS($A$2:A26)<=ROUND(COUNTA($A:$A)*80%,0),"Training","Testing") -> Training | S26: parking | T26: -1355841.9 | U26: 360630.72 | V26: -3.7596406 | W26: 0.00026345688 | X26: -2069805.5 | Y26: -641878.25 | Z26: -2069805.5 | AA26: -641878.25
A27: 5150000 | B27: 4800 | C27: 3 | D27: 2 | E27: 2 | F27: 1 | G27: 0 | H27: 1 | I27: 1 | J27: 2 | K27: 0 | L27: 0 | M27: 1 | N27: =RAND() -> 0.89745075 | O27: 0.39197383 | P27: =IF(ROWS($A$2:A27)<=ROUND(COUNTA($A:$A)*80%,0),"Training","Testing") -> Training | S27: prefarea | T27: 1513409.9 | U27: 650800.63 | V27: 2.3254585 | W27: 0.021712687 | X27: 224978.35 | Y27: 2801841.4 | Z27: 224978.35 | AA27: 2801841.4
A28: 6250000 | B28: 5800 | C28: 4 | D28: 3 | E28: 2 | F28: 1 | G28: 1 | H28: 0 | I28: 1 | J28: 2 | K28: 1 | L28: 1 | M28: 0 | N28: =RAND() -> 0.87153231 | O28: 0.3003061 | P28: =IF(ROWS($A$2:A28)<=ROUND(COUNTA($A:$A)*80%,0),"Training","Testing") -> Training | S28: furnishingstatus | T28: 2078764.6 | U28: 1159253.8 | V28: 1.793192 | W28: 0.07544027 | X28: -216284.03 | Y28: 4373813.3 | Z28: -216284.03 | AA28: 4373813.3
A29: 7550000 | B29: 6900 | C29: 5 | D29: 3 | E29: 3 | F29: 1 | G29: 1 | H29: 1 | I29: 1 | J29: 3 | K29: 1 | L29: 1 | M29: 0 | N29: =RAND() -> 0.2616773 | O29: 0.051641585 | P29: =IF(ROWS($A$2:A29)<=ROUND(COUNTA($A:$A)*80%,0),"Training","Testing") -> Training | S29: semi-furnishingstatus | T29: 475961.63 | U29: 549584.65 | V29: 0.8660388 | W29: 0.38818285 | X29: -612086.15 | Y29: 1564009.4 | Z29: -612086.15 | AA29: 1564009.4
A30: 5150000 | B30: 4800 | C30: 3 | D30: 2 | E30: 2 | F30: 1 | G30: 0 | H30: 1 | I30: 1 | J30: 2 | K30: 0 | L30: 0 | M30: 1 | N30: =RAND() -> 0.34919532 | O30: 0.79437807 | P30: =IF(ROWS($A$2:A30)<=ROUND(COUNTA($A:$A)*80%,0),"Training","Testing") -> Training
A31: 7900000 | B31: 7300 | C31: 5 | D31: 4 | E31: 3 | F31: 1 | G31: 1 | H31: 1 | I31: 1 | J31: 3 | K31: 1 | L31: 1 | M31: 0 | N31: =RAND() -> 0.94350815 | O31: 0.60967552 | P31: =IF(ROWS($A$2:A31)<=ROUND(COUNTA($A:$A)*80%,0),"Training","Testing") -> Training
A32: 13300000 | B32: 7420 | C32: 4 | D32: 2 | E32: 3 | F32: 1 | G32: 0 | H32: 0 | I32: 1 | J32: 2 | K32: 1 | L32: 1 | M32: 0 | N32: =RAND() -> 0.52001547 | O32: 0.29925624 | P32: =IF(ROWS($A$2:A32)<=ROUND(COUNTA($A:$A)*80%,0),"Training","Testing") -> Training
A33: 4850000 | B33: 4450 | C33: 3 | D33: 2 | E33: 2 | F33: 1 | G33: 0 | H33: 1 | I33: 1 | J33: 2 | K33: 0 | L33: 0 | M33: 1 | N33: =RAND() -> 0.89861978 | O33: 0.75820993 | P33: =IF(ROWS($A$2:A33)<=ROUND(COUNTA($A:$A)*80%,0),"Training","Testing") -> Training
A34: 4550000 | B34: 4200 | C34: 3 | D34: 2 | E34: 1 | F34: 0 | G34: 0 | H34: 0 | I34: 0 | J34: 2 | K34: 0 | L34: 0 | M34: 0 | N34: =RAND() -> 0.0090731985 | O34: 0.94380343 | P34: =IF(ROWS($A$2:A34)<=ROUND(COUNTA($A:$A)*80%,0),"Training","Testing") -> Training
A35: 6850000 | B35: 6250 | C35: 4 | D35: 3 | E35: 2 | F35: 1 | G35: 1 | H35: 0 | I35: 1 | J35: 2 | K35: 1 | L35: 1 | M35: 0 | N35: =RAND() -> 0.66842308 | O35: 0.25577815 | P35: =IF(ROWS($A$2:A35)<=ROUND(COUNTA($A:$A)*80%,0),"Training","Testing") -> Training
A36: 11950000 | B36: 5400 | C36: 4 | D36: 3 | E36: 2 | F36: 1 | G36: 1 | H36: 0 | I36: 1 | J36: 2 | K36: 1 | L36: 1 | M36: 0 | N36: =RAND() -> 0.016398616 | O36: 0.29053725 | P36: =IF(ROWS($A$2:A36)<=ROUND(COUNTA($A:$A)*80%,0),"Training","Testing") -> Training
A37: 6200000 | B37: 5850 | C37: 4 | D37: 3 | E37: 2 | F37: 1 | G37: 1 | H37: 0 | I37: 1 | J37: 2 | K37: 1 | L37: 1 | M37: 0 | N37: =RAND() -> 0.59406636 | O37: 0.34591715 | P37: =IF(ROWS($A$2:A37)<=ROUND(COUNTA($A:$A)*80%,0),"Training","Testing") -> Training
A38: 5250000 | B38: 4950 | C38: 3 | D38: 2 | E38: 2 | F38: 1 | G38: 0 | H38: 0 | I38: 1 | J38: 2 | K38: 0 | L38: 0 | M38: 1 | N38: =RAND() -> 0.21312447 | O38: 0.94585143 | P38: =IF(ROWS($A$2:A38)<=ROUND(COUNTA($A:$A)*80%,0),"Training","Testing") -> Training
A39: 4950000 | B39: 4550 | C39: 3 | D39: 2 | E39: 2 | F39: 1 | G39: 0 | H39: 0 | I39: 1 | J39: 2 | K39: 0 | L39: 0 | M39: 1 | N39: =RAND() -> 0.54958769 | O39: 0.52446702 | P39: =IF(ROWS($A$2:A39)<=ROUND(COUNTA($A:$A)*80%,0),"Training","Testing") -> Training
A40: 4050000 | B40: 3650 | C40: 3 | D40: 2 | E40: 1 | F40: 0 | G40: 0 | H40: 0 | I40: 0 | J40: 1 | K40: 0 | L40: 0 | M40: 0 | N40: =RAND() -> 0.24652606 | O40: 0.43172683 | P40: =IF(ROWS($A$2:A40)<=ROUND(COUNTA($A:$A)*80%,0),"Training","Testing") -> Training
...

Sheet test
A1: price | B1: area | C1: bedrooms | D1: bathrooms | E1: stories | F1: mainroad | G1: guestroom | H1: basement | I1: airconditioning | J1: parking | K1: prefarea | L1: furnishingstatus | M1: semi-furnishingstatus | N1: Random | O1: Random (values) | P1: Dataset | Q1: predicted_price | R1: Error | S1: Absolute_Error | T1: Squared_Error
A2: 5650000 | B2: 5300 | C2: 4 | D2: 2 | E2: 2 | F2: 1 | G2: 0 | H2: 1 | I2: 1 | J2: 2 | K2: 0 | L2: 0 | M2: 1 | N2: 0.076113382 | O2: 0.41556999 | P2: Testing | Q2: =train!T$17+train!T$18*test!B2+train!T$19*test!C2+train!T$20*test!D2+train!T$21*test!E2+train!T$22*test!F2+train!T$23*test!G2+train!T$24*test!H2+train!T$25*test!I2+train!T$26*test!J2+train!T$27*K2+train!T$28*test!L2+train!T$29*test!M2 -> 5895037.9 | R2: =A2-Q2 -> -245037.91 | S2: =ABS(R2) -> 245037.91 | T2: =R2^2 -> 6.0043578e+10 | V2: MAE | W2: MSE | X2: RMSE | Y2: R²
A3: 7600000 | B3: 4100 | C3: 3 | D3: 1 | E3: 2 | F3: 1 | G3: 0 | H3: 1 | I3: 0 | J3: 1 | K3: 0 | L3: 0 | M3: 1 | N3: 0.8566223 | O3: 0.60194014 | P3: Testing | Q3: =train!T$17+train!T$18*test!B3+train!T$19*test!C3+train!T$20*test!D3+train!T$21*test!E3+train!T$22*test!F3+train!T$23*test!G3+train!T$24*test!H3+train!T$25*test!I3+train!T$26*test!J3+train!T$27*K3+train!T$28*test!L3+train!T$29*test!M3 -> 6541567.9 | R3: =A3-Q3 -> 1058432.1 | S3: =ABS(R3) -> 1058432.1 | T3: =R3^2 -> 1.1202785e+12 | V3: =AVERAGE(S2:S33) -> 484285.12 | W3: =AVERAGE(T2:T33) -> 3.4054082e+11 | X3: =SQRT(W3) -> 583558.75 | Y3: =1-SUM(T2:T33)/DEVSQ(A2:A33) -> 0.91896106
A4: 4400000 | B4: 4050 | C4: 3 | D4: 2 | E4: 1 | F4: 0 | G4: 0 | H4: 0 | I4: 0 | J4: 2 | K4: 0 | L4: 0 | M4: 1 | N4: 0.36619264 | O4: 0.36702778 | P4: Testing | Q4: =train!T$17+train!T$18*test!B4+train!T$19*test!C4+train!T$20*test!D4+train!T$21*test!E4+train!T$22*test!F4+train!T$23*test!G4+train!T$24*test!H4+train!T$25*test!I4+train!T$26*test!J4+train!T$27*K4+train!T$28*test!L4+train!T$29*test!M4 -> 3869343.1 | R4: =A4-Q4 -> 530656.86 | S4: =ABS(R4) -> 530656.86 | T4: =R4^2 -> 2.815967e+11
A5: 8350000 | B5: 7600 | C5: 5 | D5: 4 | E5: 3 | F5: 1 | G5: 1 | H5: 1 | I5: 1 | J5: 3 | K5: 1 | L5: 1 | M5: 0 | N5: 0.40403669 | O5: 0.80305884 | P5: Testing | Q5: =train!T$17+train!T$18*test!B5+train!T$19*test!C5+train!T$20*test!D5+train!T$21*test!E5+train!T$22*test!F5+train!T$23*test!G5+train!T$24*test!H5+train!T$25*test!I5+train!T$26*test!J5+train!T$27*K5+train!T$28*test!L5+train!T$29*test!M5 -> 8622721 | R5: =A5-Q5 -> -272721 | S5: =ABS(R5) -> 272721 | T5: =R5^2 -> 7.4376746e+10
A6: 7350000 | B6: 6700 | C6: 5 | D6: 3 | E6: 3 | F6: 1 | G6: 1 | H6: 1 | I6: 1 | J6: 3 | K6: 1 | L6: 1 | M6: 0 | N6: 0.6428308 | O6: 0.37174426 | P6: Testing | Q6: =train!T$17+train!T$18*test!B6+train!T$19*test!C6+train!T$20*test!D6+train!T$21*test!E6+train!T$22*test!F6+train!T$23*test!G6+train!T$24*test!H6+train!T$25*test!I6+train!T$26*test!J6+train!T$27*K6+train!T$28*test!L6+train!T$29*test!M6 -> 7103536.6 | R6: =A6-Q6 -> 246463.42 | S6: =ABS(R6) -> 246463.42 | T6: =R6^2 -> 6.0744218e+10
A7: 7150000 | B7: 6500 | C7: 5 | D7: 3 | E7: 3 | F7: 1 | G7: 1 | H7: 1 | I7: 1 | J7: 3 | K7: 1 | L7: 1 | M7: 0 | N7: 0.28401268 | O7: 0.54834885 | P7: Testing | Q7: =train!T$17+train!T$18*test!B7+train!T$19*test!C7+train!T$20*test!D7+train!T$21*test!E7+train!T$22*test!F7+train!T$23*test!G7+train!T$24*test!H7+train!T$25*test!I7+train!T$26*test!J7+train!T$27*K7+train!T$28*test!L7+train!T$29*test!M7 -> 6666678.2 | R7: =A7-Q7 -> 483321.76 | S7: =ABS(R7) -> 483321.76 | T7: =R7^2 -> 2.3359992e+11
A8: 4550000 | B8: 4200 | C8: 3 | D8: 2 | E8: 2 | F8: 0 | G8: 0 | H8: 0 | I8: 0 | J8: 2 | K8: 0 | L8: 0 | M8: 0 | N8: 0.61810856 | O8: 0.39606356 | P8: Testing | Q8: =train!T$17+train!T$18*test!B8+train!T$19*test!C8+train!T$20*test!D8+train!T$21*test!E8+train!T$22*test!F8+train!T$23*test!G8+train!T$24*test!H8+train!T$25*test!I8+train!T$26*test!J8+train!T$27*K8+train!T$28*test!L8+train!T$29*test!M8 -> 4253122.3 | R8: =A8-Q8 -> 296877.69 | S8: =ABS(R8) -> 296877.69 | T8: =R8^2 -> 8.8136362e+10
A9: 3950000 | B9: 3500 | C9: 2 | D9: 1 | E9: 1 | F9: 0 | G9: 0 | H9: 0 | I9: 0 | J9: 1 | K9: 0 | L9: 0 | M9: 0 | N9: 0.78143727 | O9: 0.90401989 | P9: Testing | Q9: =train!T$17+train!T$18*test!B9+train!T$19*test!C9+train!T$20*test!D9+train!T$21*test!E9+train!T$22*test!F9+train!T$23*test!G9+train!T$24*test!H9+train!T$25*test!I9+train!T$26*test!J9+train!T$27*K9+train!T$28*test!L9+train!T$29*test!M9 -> 4797719.9 | R9: =A9-Q9 -> -847719.93 | S9: =ABS(R9) -> 847719.93 | T9: =R9^2 -> 7.1862909e+11
A10: 3550000 | B10: 3000 | C10: 2 | D10: 1 | E10: 1 | F10: 0 | G10: 0 | H10: 0 | I10: 0 | J10: 1 | K10: 0 | L10: 0 | M10: 0 | N10: 0.37803331 | O10: 0.51110892 | P10: Testing | Q10: =train!T$17+train!T$18*test!B10+train!T$19*test!C10+train!T$20*test!D10+train!T$21*test!E10+train!T$22*test!F10+train!T$23*test!G10+train!T$24*test!H10+train!T$25*test!I10+train!T$26*test!J10+train!T$27*K10+train!T$28*test!L10+train!T$29*test!M10 -> 3705574.1 | R10: =A10-Q10 -> -155574.09 | S10: =ABS(R10) -> 155574.09 | T10: =R10^2 -> 2.4203297e+10
A11: 7200000 | B11: 6400 | C11: 4 | D11: 3 | E11: 3 | F11: 1 | G11: 1 | H11: 1 | I11: 1 | J11: 2 | K11: 1 | L11: 1 | M11: 0 | N11: 0.21154451 | O11: 0.67871829 | P11: Testing | Q11: =train!T$17+train!T$18*test!B11+train!T$19*test!C11+train!T$20*test!D11+train!T$21*test!E11+train!T$22*test!F11+train!T$23*test!G11+train!T$24*test!H11+train!T$25*test!I11+train!T$26*test!J11+train!T$27*K11+train!T$28*test!L11+train!T$29*test!M11 -> 8607269.8 | R11: =A11-Q11 -> -1407269.8 | S11: =ABS(R11) -> 1407269.8 | T11: =R11^2 -> 1.9804084e+12
A12: 13650000 | B12: 7500 | C12: 4 | D12: 2 | E12: 2 | F12: 1 | G12: 0 | H12: 1 | I12: 1 | J12: 3 | K12: 1 | L12: 1 | M12: 0 | N12: 0.75990228 | O12: 0.023301642 | P12: Testing | Q12: =train!T$17+train!T$18*test!B12+train!T$19*test!C12+train!T$20*test!D12+train!T$21*test!E12+train!T$22*test!F12+train!T$23*test!G12+train!T$24*test!H12+train!T$25*test!I12+train!T$26*test!J12+train!T$27*K12+train!T$28*test!L12+train!T$29*test!M12 -> 12460851 | R12: =A12-Q12 -> 1189149.4 | S12: =ABS(R12) -> 1189149.4 | T12: =R12^2 -> 1.4140762e+12
A13: 6850000 | B13: 6250 | C13: 4 | D13: 3 | E13: 2 | F13: 1 | G13: 1 | H13: 0 | I13: 1 | J13: 2 | K13: 1 | L13: 1 | M13: 0 | N13: 0.76131506 | O13: 0.27926836 | P13: Testing | Q13: =train!T$17+train!T$18*test!B13+train!T$19*test!C13+train!T$20*test!D13+train!T$21*test!E13+train!T$22*test!F13+train!T$23*test!G13+train!T$24*test!H13+train!T$25*test!I13+train!T$26*test!J13+train!T$27*K13+train!T$28*test!L13+train!T$29*test!M13 -> 7475647.3 | R13: =A13-Q13 -> -625647.34 | S13: =ABS(R13) -> 625647.34 | T13: =R13^2 -> 3.9143459e+11
A14: 8250000 | B14: 7600 | C14: 5 | D14: 4 | E14: 3 | F14: 1 | G14: 1 | H14: 1 | I14: 1 | J14: 3 | K14: 1 | L14: 1 | M14: 0 | N14: 0.50719504 | O14: 0.53967634 | P14: Testing | Q14: =train!T$17+train!T$18*test!B14+train!T$19*test!C14+train!T$20*test!D14+train!T$21*test!E14+train!T$22*test!F14+train!T$23*test!G14+train!T$24*test!H14+train!T$25*test!I14+train!T$26*test!J14+train!T$27*K14+train!T$28*test!L14+train!T$29*test!M14 -> 8622721 | R14: =A14-Q14 -> -372721 | S14: =ABS(R14) -> 372721 | T14: =R14^2 -> 1.3892095e+11
A15: 4650000 | B15: 4300 | C15: 3 | D15: 2 | E15: 2 | F15: 1 | G15: 0 | H15: 0 | I15: 0 | J15: 2 | K15: 0 | L15: 0 | M15: 1 | N15: 0.83247552 | O15: 0.97194633 | P15: Testing | Q15: =train!T$17+train!T$18*test!B15+train!T$19*test!C15+train!T$20*test!D15+train!T$21*test!E15+train!T$22*test!F15+train!T$23*test!G15+train!T$24*test!H15+train!T$25*test!I15+train!T$26*test!J15+train!T$27*K15+train!T$28*test!L15+train!T$29*test!M15 -> 4904024.6 | R15: =A15-Q15 -> -254024.56 | S15: =ABS(R15) -> 254024.56 | T15: =R15^2 -> 6.4528478e+10
... A33: 4100000 | B33: 3550 | C33: 2 | D33: 1 | E33: 1 | F33: 0 | G33: 0 | H33: 0 | I33: 0 | J33: 1 | K33: 0 | L33: 0 | M33: 0 | N33: 0.20637966 | O33: 0.58282977 | P33: Testing | Q33: =train!T$17+train!T$18*test!B33+train!T$19*test!C33+train!T$20*test!D33+train!T$21*test!E33+train!T$22*test!F33+train!T$23*test!G33+train!T$24*test!H33+train!T$25*test!I33+train!T$26*test!J33+train!T$27*K33+train!T$28*test!L33+train!T$29*test!M33 -> 4906934.5 | R33: =A33-Q33 -> -806934.52 | S33: =ABS(R33) -> 806934.52 | T33: =R33^2 -> 6.5114332e+11
F34: T O T A L | Q34: =SUM(Q2:Q33) -> 1.9348835e+08 | R34: =SUM(R2:R33) -> -4288353.8 | S34: =ABS(R34) -> 4288353.8 | T34: =R34^2 -> 1.8389978e+13
